<?xml version="1.0" ?>

<robot xmlns:xacro="http://www.ros.org/wiki/xacro" name="WSTTA_ROBOT">
  <!--<xacro:include filename="file://$(find mm_bringup)/urdf/MyRobot_gz.gazebo" />-->
  <!--<xacro:include filename="$(find mm_bringup)/urdf/MyRobot.ros2control" />-->
  <xacro:include filename="$(find mm_bringup)/urdf/materials.xacro" />
  <xacro:include filename="$(find mm_bringup)/urdf/arm.xacro" />
  <xacro:include filename="$(find mm_bringup)/urdf/lidar.xacro" />
  <xacro:include filename="$(find mm_bringup)/urdf/imu.xacro" />
  <xacro:include filename="$(find mm_bringup)/urdf/camera.xacro" />
  <xacro:include filename="$(find mm_bringup)/urdf/ultrasonic.xacro" />
  <!--base foot print link for odometry-->
  <link name="base_footprint" />
  <joint name="base_footprint_base_link" type="fixed">
    <origin xyz="0.0 0.0 0.0" rpy="0.0 0.0 0.0"/>
    <parent
      link="base_footprint" />
    <child
      link="base_link" />
  </joint>
  <link
    name="base_link">
    <inertial>
      <origin
        xyz="0.0009926 0.0019362 0.044759"
        rpy="0 0 0" />
      <mass
        value="1.742" />
      <inertia
        ixx="0.018183"
        ixy="-2.9255E-05"
        ixz="4.4241E-05"
        iyy="0.027172"
        iyz="-5.1965E-05"
        izz="0.043318" />
    </inertial>
    <visual>
      <origin
        xyz="0 0 0"
        rpy="0 0 0" />
      <geometry>
        <mesh
          filename="file://$(find mm_bringup)/meshes/base_link.STL" />
      </geometry>
      <material
        name="">
        <color
          rgba="0.113725490196078 0.207843137254902 0.349019607843137 1" />
      </material>
    </visual>
    <collision>
      <origin
        xyz="0 0 0"
        rpy="0 0 0" />
      <geometry>
        <mesh
          filename="file://$(find mm_bringup)/meshes/base_link_c.STL" />
      </geometry>
    </collision>
  </link>
  <link
    name="left_front_wheel_link">
    <inertial>
      <origin
        xyz="1.9358E-06 0.01449 1.8677E-06"
        rpy="0 0 0" />
      <mass
        value="0.11904" />
      <inertia
        ixx="0.00015193"
        ixy="6.9518E-09"
        ixz="1.2783E-09"
        iyy="0.00023025"
        iyz="6.731E-09"
        izz="0.00015193" />
    </inertial>
    <visual>
      <origin
        xyz="0 0 0"
        rpy="0 0 0" />
      <geometry>
        <mesh
          filename="file://$(find mm_bringup)/meshes/left_front_wheel_link.STL" />
      </geometry>
      <material
        name="">
        <color
          rgba="0.29804 0.29804 0.29804 1" />
      </material>
    </visual>
    <collision>
      <origin
        xyz="0 0 0"
        rpy="0 0 0" />
      <geometry>
        <mesh
          filename="file://$(find mm_bringup)/meshes/left_rear_wheel_link_c.STL" />
      </geometry>
    </collision>
  </link>
  <joint
    name="left_front_wheel_joint"
    type="continuous">
    <origin
      xyz="0.10969 0.16824 0.0165"
      rpy="0 0 0" />
    <parent
      link="base_link" />
    <child
      link="left_front_wheel_link" />
    <axis
      xyz="0 1 0" />
    <dynamics
      damping="0.5"
      friction="0.1" />
  </joint>
  <link
    name="left_rear_wheel_link">
    <inertial>
      <origin
        xyz="-8.6382E-05 0.01449 4.5072E-05"
        rpy="0 0 0" />
      <mass
        value="0.11904" />
      <inertia
        ixx="0.00015193"
        ixy="8.59E-09"
        ixz="-1.0577E-09"
        iyy="0.00023025"
        iyz="-4.4616E-09"
        izz="0.00015193" />
    </inertial>
    <visual>
      <origin
        xyz="0 0 0"
        rpy="0 0 0" />
      <geometry>
        <mesh
          filename="file://$(find mm_bringup)/meshes/left_rear_wheel_link.STL" />
      </geometry>
      <material
        name="">
        <color
          rgba="0.29804 0.29804 0.29804 1" />
      </material>
    </visual>
    <collision>
      <origin
        xyz="0 0 0"
        rpy="0 0 0" />
      <geometry>
        <mesh
          filename="file://$(find mm_bringup)/meshes/left_rear_wheel_link_c.STL" />
      </geometry>
    </collision>
  </link>
  <joint
    name="left_rear_wheel_joint"
    type="continuous">
    <origin
      xyz="-0.11022 0.16824 0.016454"
      rpy="0 0 0" />
    <parent
      link="base_link" />
    <child
      link="left_rear_wheel_link" />
    <axis
      xyz="0 1 0" />
    <dynamics
      damping="0.5"
      friction="0.1" />
    <mimic
      joint="left_front_wheel_joint"
      multiplier="1"
      offset="0" />
  </joint>
  <link
    name="right_front_wheel_link">
    <inertial>
      <origin
        xyz="-2.68469087316703E-06 -0.0144898485914691 -2.38918705097735E-07"
        rpy="0 0 0" />
      <mass
        value="0.119038146481528" />
      <inertia
        ixx="0.000151931968900047"
        ixy="9.64070623015234E-09"
        ixz="2.06886947122579E-10"
        iyy="0.000230248929387245"
        iyz="8.22157781827375E-10"
        izz="0.000151929483046792" />
    </inertial>
    <visual>
      <origin
        xyz="0 0 0"
        rpy="0 0 0" />
      <geometry>
        <mesh
          filename="file://$(find mm_bringup)/meshes/right_front_wheel_link.STL" />
      </geometry>
      <material
        name="">
        <color
          rgba="0.298039215686275 0.298039215686275 0.298039215686275 1" />
      </material>
    </visual>
    <collision>
      <origin
        xyz="0 0 0"
        rpy="0 0 0" />
      <geometry>
        <mesh
          filename="file://$(find mm_bringup)/meshes/right_front_wheel_link_c.STL" />
      </geometry>
    </collision>
  </link>
  <joint
    name="right_front_wheel_joint"
    type="continuous">
    <origin
      xyz="0.10969 -0.16776 0.0165"
      rpy="0 0 0" />
    <parent
      link="base_link" />
    <child
      link="right_front_wheel_link" />
    <axis
      xyz="0 1 0" />
    <dynamics
      damping="0.5"
      friction="0.1" />
  </joint>
  <link
    name="right_rear_wheel_link">
    <inertial>
      <origin
        xyz="-9.18065809774049E-05 -0.0144898421944957 -3.26599531583205E-05"
        rpy="0 0 0" />
      <mass
        value="0.119038159969982" />
      <inertia
        ixx="0.000151931672363267"
        ixy="-9.09099150002439E-09"
        ixz="8.20737861022572E-10"
        iyy="0.000230248991142072"
        iyz="-3.25295725432534E-09"
        izz="0.000151929718320073" />
    </inertial>
    <visual>
      <origin
        xyz="0 0 0"
        rpy="0 0 0" />
      <geometry>
        <mesh
          filename="file://$(find mm_bringup)/meshes/right_rear_wheel_link.STL" />
      </geometry>
      <material
        name="">
        <color
          rgba="0.298039215686275 0.298039215686275 0.298039215686275 1" />
      </material>
    </visual>
    <collision>
      <origin
        xyz="0 0 0"
        rpy="0 0 0" />
      <geometry>
        <mesh
          filename="file://$(find mm_bringup)/meshes/right_front_wheel_link_c.STL" />
      </geometry>
    </collision>
  </link>
  <joint
    name="right_rear_wheel_joint"
    type="continuous">
    <origin
      xyz="-0.11022 -0.16776 0.016534"
      rpy="0 0 0" />
    <parent
      link="base_link" />
    <child
      link="right_rear_wheel_link" />
    <axis
      xyz="0 1 0" />
    <dynamics
      damping="0.5"
      friction="0.1" />
    <mimic
      joint="right_front_wheel_joint"
      multiplier="1"
      offset="0" />
  </joint>

  <link
    name="recipient_Link">
    <inertial>
      <origin
        xyz="-2.22044604925031E-16 2.22044604925031E-16 0.0267296895245414"
        rpy="0 0 0" />
      <mass
        value="0.217690400735568" />
      <inertia
        ixx="0.000695386873840761"
        ixy="-2.57498015965307E-19"
        ixz="4.16912900503068E-19"
        iyy="0.00069538687384076"
        iyz="-1.0905491269373E-19"
        izz="0.000866872476711265" />
    </inertial>
    <visual>
      <origin
        xyz="0 0 0"
        rpy="0 0 0" />
      <geometry>
        <mesh
          filename="file://$(find mm_bringup)/meshes/recipient_Link.STL" />
      </geometry>
      <material
        name="">
        <color
          rgba="0.298039215686275 0.298039215686275 0.298039215686275 1" />
      </material>
    </visual>
    <collision>
      <origin
        xyz="0 0 0"
        rpy="0 0 0" />
      <geometry>
        <mesh
          filename="file://$(find mm_bringup)/meshes/recipient_Link_c.STL" />
      </geometry>
    </collision>
  </link>
  <joint
    name="recipient_joint"
    type="fixed">
    <origin
      xyz="-0.08531 0.00023801 0.0955"
      rpy="0 0 0" />
    <parent
      link="base_link" />
    <child
      link="recipient_Link" />
    <axis
      xyz="0 0 0" />
  </joint>
  
</robot>